<?xml version="1.0" encoding="utf-8"?>
<!-- =================================================================================== -->
<!-- |    This document was autogenerated by xacro from ur5e_robot.urdf.xacro          | -->
<!-- |    EDITING THIS FILE BY HAND IS NOT RECOMMENDED                                 | -->
<!-- =================================================================================== -->
<robot name="ur5e" xmlns:xacro="http://ros.org/wiki/xacro">
  <link name="base_link">
    <visual>
      <geometry>
        <mesh filename="package://ur5e_hand/urdf/meshes/ur5e/visual/base.dae"/>
      </geometry>
      <material name="LightGrey">
        <color rgba="0.7 0.7 0.7 1.0"/>
      </material>
    </visual>
    <collision>
      <geometry>
        <mesh filename="package://ur5e_hand/urdf/meshes/ur5e/collision/base.stl" scale="1.0 1.0 1.0"/>
      </geometry>
    </collision>
    <inertial>
      <mass value="4.0"/>
      <origin rpy="0 0 0" xyz="0.0 0.0 0.0"/>
      <inertia ixx="0.00443333156" ixy="0.0" ixz="0.0" iyy="0.00443333156" iyz="0.0" izz="0.0072"/>
    </inertial>
  </link>
  <joint name="shoulder_pan_joint" type="revolute">
    <parent link="base_link"/>
    <child link="shoulder_link"/>
    <origin rpy="0.0 0.0 0.0" xyz="0.0 0.0 0.163"/>
    <axis xyz="0 0 1"/>
    <limit effort="150.0" lower="-6.28318530718" upper="6.28318530718" velocity="3.14"/>
    <dynamics damping="0.0" friction="0.0"/>
  </joint>
  <link name="shoulder_link">
    <visual>
      <geometry>
        <mesh filename="package://ur5e_hand/urdf/meshes/ur5e/visual/shoulder.dae"/>
      </geometry>
      <material name="LightGrey">
        <color rgba="0.7 0.7 0.7 1.0"/>
      </material>
    </visual>
    <collision>
      <geometry>
        <mesh filename="package://ur5e_hand/urdf/meshes/ur5e/collision/shoulder.stl" scale="1.0 1.0 1.0"/>
      </geometry>
    </collision>
    <inertial>
      <mass value="3.7"/>
      <origin rpy="0 0 0" xyz="0.0 0.0 0.0"/>
      <inertia ixx="0.010267495893" ixy="0.0" ixz="0.0" iyy="0.010267495893" iyz="0.0" izz="0.00666"/>
    </inertial>
  </link>
  <joint name="shoulder_lift_joint" type="revolute">
    <parent link="shoulder_link"/>
    <child link="upper_arm_link"/>
    <origin rpy="0.0 1.57079632679 0.0" xyz="0.0 0.138 0.0"/>
    <axis xyz="0 1 0"/>
    <limit effort="150.0" lower="-6.28318530718" upper="6.28318530718" velocity="3.14"/>
    <dynamics damping="0.0" friction="0.0"/>
  </joint>
  <link name="upper_arm_link">
    <visual>
      <geometry>
        <mesh filename="package://ur5e_hand/urdf/meshes/ur5e/visual/upperarm.dae"/>
      </geometry>
      <material name="LightGrey">
        <color rgba="0.7 0.7 0.7 1.0"/>
      </material>
    </visual>
    <collision>
      <geometry>
        <mesh filename="package://ur5e_hand/urdf/meshes/ur5e/collision/upperarm.stl" scale="1.0 1.0 1.0"/>
      </geometry>
    </collision>
    <inertial>
      <mass value="8.393"/>
      <origin rpy="0 0 0" xyz="0.0 0.0 0.2125"/>
      <inertia ixx="0.133885781862" ixy="0.0" ixz="0.0" iyy="0.133885781862" iyz="0.0" izz="0.0151074"/>
    </inertial>
  </link>
  <joint name="elbow_joint" type="revolute">
    <parent link="upper_arm_link"/>
    <child link="forearm_link"/>
    <origin rpy="0.0 0.0 0.0" xyz="0.0 -0.131 0.425"/>
    <axis xyz="0 1 0"/>
    <limit effort="150.0" lower="-3.14159265359" upper="3.14159265359" velocity="3.14"/>
    <dynamics damping="0.0" friction="0.0"/>
  </joint>
  <link name="forearm_link">
    <visual>
      <geometry>
        <mesh filename="package://ur5e_hand/urdf/meshes/ur5e/visual/forearm.dae"/>
      </geometry>
      <material name="LightGrey">
        <color rgba="0.7 0.7 0.7 1.0"/>
      </material>
    </visual>
    <collision>
      <geometry>
        <mesh filename="package://ur5e_hand/urdf/meshes/ur5e/collision/forearm.stl" scale="1.0 1.0 1.0"/>
      </geometry>
    </collision>
    <inertial>
      <mass value="2.275"/>
      <origin rpy="0 0 0" xyz="0.0 0.0 0.196"/>
      <inertia ixx="0.0311796208615" ixy="0.0" ixz="0.0" iyy="0.0311796208615" iyz="0.0" izz="0.004095"/>
    </inertial>
  </link>
  <joint name="wrist_1_joint" type="revolute">
    <parent link="forearm_link"/>
    <child link="wrist_1_link"/>
    <origin rpy="0.0 1.57079632679 0.0" xyz="0.0 0.0 0.392"/>
    <axis xyz="0 1 0"/>
    <limit effort="28.0" lower="-6.28318530718" upper="6.28318530718" velocity="6.28"/>
    <dynamics damping="0.0" friction="0.0"/>
  </joint>
  <link name="wrist_1_link">
    <visual>
      <geometry>
        <mesh filename="package://ur5e_hand/urdf/meshes/ur5e/visual/wrist1.dae"/>
      </geometry>
      <material name="LightGrey">
        <color rgba="0.7 0.7 0.7 1.0"/>
      </material>
    </visual>
    <collision>
      <geometry>
        <mesh filename="package://ur5e_hand/urdf/meshes/ur5e/collision/wrist1.stl" scale="1.0 1.0 1.0"/>
      </geometry>
    </collision>
    <inertial>
      <mass value="1.219"/>
      <origin rpy="0 0 0" xyz="0.0 0.127 0.0"/>
      <inertia ixx="0.00255989897604" ixy="0.0" ixz="0.0" iyy="0.00255989897604" iyz="0.0" izz="0.0021942"/>
    </inertial>
  </link>
  <joint name="wrist_2_joint" type="revolute">
    <parent link="wrist_1_link"/>
    <child link="wrist_2_link"/>
    <origin rpy="0.0 0.0 0.0" xyz="0.0 0.127 0.0"/>
    <axis xyz="0 0 1"/>
    <limit effort="28.0" lower="-6.28318530718" upper="6.28318530718" velocity="6.28"/>
    <dynamics damping="0.0" friction="0.0"/>
  </joint>
  <link name="wrist_2_link">
    <visual>
      <geometry>
        <mesh filename="package://ur5e_hand/urdf/meshes/ur5e/visual/wrist2.dae"/>
      </geometry>
      <material name="LightGrey">
        <color rgba="0.7 0.7 0.7 1.0"/>
      </material>
    </visual>
    <collision>
      <geometry>
        <mesh filename="package://ur5e_hand/urdf/meshes/ur5e/collision/wrist2.stl" scale="1.0 1.0 1.0"/>
      </geometry>
    </collision>
    <inertial>
      <mass value="1.219"/>
      <origin rpy="0 0 0" xyz="0.0 0.0 0.1"/>
      <inertia ixx="0.00255989897604" ixy="0.0" ixz="0.0" iyy="0.00255989897604" iyz="0.0" izz="0.0021942"/>
    </inertial>
  </link>
  <joint name="wrist_3_joint" type="revolute">
    <parent link="wrist_2_link"/>
    <child link="wrist_3_link"/>
    <origin rpy="0.0 0.0 0.0" xyz="0.0 0.0 0.1"/>
    <axis xyz="0 1 0"/>
    <limit effort="28.0" lower="-6.28318530718" upper="6.28318530718" velocity="6.28"/>
    <dynamics damping="0.0" friction="0.0"/>
  </joint>
  <link name="wrist_3_link">
    <visual>
      <geometry>
        <mesh filename="package://ur5e_hand/urdf/meshes/ur5e/visual/wrist3.dae"/>
      </geometry>
      <material name="LightGrey">
        <color rgba="0.7 0.7 0.7 1.0"/>
      </material>
    </visual>
    <collision>
      <geometry>
        <mesh filename="package://ur5e_hand/urdf/meshes/ur5e/collision/wrist3.stl" scale="1.0 1.0 1.0"/>
      </geometry>
    </collision>
    <inertial>
      <mass value="0.1879"/>
      <origin rpy="1.57079632679 0 0" xyz="0.0 0.0771 0.0"/>
      <inertia ixx="9.89041005217e-05" ixy="0.0" ixz="0.0" iyy="9.89041005217e-05" iyz="0.0" izz="0.0001321171875"/>
    </inertial>
  </link>
  <joint name="ee_fixed_joint" type="fixed">
    <parent link="wrist_3_link"/>
    <child link="ee_link"/>
    <origin rpy="0.0 0.0 1.57079632679" xyz="0.0 0.1 0.0"/>
  </joint>
  <link name="ee_link">
    <collision>
      <geometry>
        <box size="0.01 0.01 0.01"/>
      </geometry>
      <origin rpy="0 0 0" xyz="-0.01 0 0"/>
    </collision>
  </link>




  <material name="black">
    <color rgba="0 0 0 1"/>
  </material>
  <material name="gray">
    <color rgba="0.1 0.1 0.1 1"/>
  </material>
  <material name="lightgray">
    <color rgba="0.8 0.8 0.8 1"/>
  </material>

  <link name="palm_link">
    <visual>
      <origin rpy="0.0 0.0 0.0" xyz="0.0 0.0 0.0"/>
      <geometry>
        <cylinder length="0.07" radius="0.15"/>
      </geometry>
      <material name="gray"/>
    </visual>
  </link>

  <joint name="ee_hand_joint" type="fixed">
    <parent link="ee_link"/>
    <child link="palm_link"/>
    <origin rpy="0.0 1.57079632679 0.0" xyz="0.0 0.0 0.0"/>
  </joint>


  <!-- Finger 1 -->
  <link name="finger1_proximal">
    <visual>
      <origin rpy="0 0 0" xyz="0 0 0" />
      <geometry>
        <mesh filename="package://hand/urdf/meshes/visual/proximal.dae"/>
      </geometry>
      <material name="gray"/>
    </visual>
    <collision>
      <origin rpy="0 0 0" xyz="0 0 0" />
      <geometry>
        <mesh filename="package://hand/urdf/meshes/collision/proximal.obj"/>
      </geometry>
    </collision>
    <inertial>
      <mass value="0.100"/>
    </inertial>
  </link>
  <link name="finger1_middle">
    <visual>
      <origin rpy="0 0 0" xyz="0 0 0" />
      <geometry>
        <mesh filename="package://hand/urdf/meshes/visual/middle.dae"/>
      </geometry>
      <material name="gray"/>
    </visual>
    <collision>
      <origin rpy="0 0 0" xyz="0 0 0" />
      <geometry>
        <mesh filename="package://hand/urdf/meshes/collision/middle.obj"/>
      </geometry>
    </collision>
    <inertial>
      <mass value="0.100"/>
    </inertial>
  </link>
  <link name="finger1_distal">
    <visual>
      <origin rpy="0 3.14159265359 0" xyz="0 0 0"/>
      <geometry>
        <mesh filename="package://hand/urdf/meshes/visual/distal.dae"/>
      </geometry>
      <material name="lightgray"/>
    </visual>
<!--    <visual name="tip">-->
<!--      <origin xyz="0 0 0"/>-->
<!--      <geometry>-->
<!--        <sphere radius="0.019"/>-->
<!--      </geometry>-->
<!--    </visual>-->
<!--    <visual name="body">-->
<!--      <origin xyz="0 0 -0.03075"/>-->
<!--      <geometry>-->
<!--        <cylinder length="0.0615" radius="0.019"/>-->
<!--      </geometry>-->
<!--    </visual>-->
    <collision name="tip">
      <origin rpy="-1.57079633 1.57079633 0" xyz="0.0 0.1043 0.0"/>
      <geometry>
        <sphere radius="0.019"/>
      </geometry>
    </collision>
    <collision name="body">
      <origin rpy="-1.57079633 1.57079633 0" xyz="0 0.06358 0.0"/>
      <geometry>
        <cylinder length="0.0815" radius="0.019"/>
      </geometry>
    </collision>
    <inertial>
      <mass value="0.11"/>
      <inertia ixx="0.01" ixy="0.00" ixz="0.00" iyy="0.01" iyz="0.0" izz="0.01"/>
      <!-- inertia is recomputed when loading asset  -->
    </inertial>
  </link>
  <link name="finger1_distal_tip">
  </link>
  <joint name="finger1_proximal_joint" type="revolute">
    <parent link="palm_link"/>
    <child link="finger1_proximal"/>
    <origin rpy="1.57079633 0 1.57079633" xyz="0.14142136 0.0 0.041"/>
    <axis xyz="0 1 0"/>
    <limit effort="4" velocity="1.0" lower="-1.0" upper="1.0"/>
  </joint>
  <joint name="finger1_middle_joint" type="revolute">
    <parent link="finger1_proximal"/>
    <child link="finger1_middle"/>
    <origin rpy="0 0 0" xyz="0.0 0.0655 0.0"/>
    <axis xyz="-1 0 0"/>
    <limit effort="4" velocity="1.0" lower="0.0" upper="1.0"/>
  </joint>
  <joint name="finger1_distal_joint" type="revolute">
    <parent link="finger1_middle"/>
    <child link="finger1_distal"/>
    <origin rpy="0 0 0" xyz="0.0 0.069 0.0"/>
    <axis xyz="-1 0 0"/>
    <limit effort="4" velocity="1.0" lower="0.0" upper="1.0"/>
  </joint>
  <joint name="finger1_distal_tip_joint" type="fixed">
    <parent link="finger1_distal"/>
    <child link="finger1_distal_tip"/>
    <origin rpy="-1.57079633 1.57079633 0" xyz="0.0 0.1035 0.0"/>
  </joint>

  <!-- Finger 2 -->
  <link name="finger2_proximal">
    <visual>
      <origin rpy="0 0 0" xyz="0 0 0" />
      <geometry>
        <mesh filename="package://hand/urdf/meshes/visual/proximal.dae"/>
      </geometry>
      <material name="gray"/>
    </visual>
    <collision>
      <origin rpy="0 0 0" xyz="0 0 0" />
      <geometry>
        <mesh filename="package://hand/urdf/meshes/collision/proximal.obj"/>
      </geometry>
    </collision>
    <inertial>
      <mass value="0.100"/>
    </inertial>
  </link>
  <link name="finger2_middle">
    <visual>
      <origin rpy="0 0 0" xyz="0 0 0" />
      <geometry>
        <mesh filename="package://hand/urdf/meshes/visual/middle.dae"/>
      </geometry>
      <material name="gray"/>
    </visual>
    <collision>
      <origin rpy="0 0 0" xyz="0 0 0" />
      <geometry>
        <mesh filename="package://hand/urdf/meshes/collision/middle.obj"/>
      </geometry>
    </collision>
    <inertial>
      <mass value="0.100"/>
    </inertial>
  </link>
  <link name="finger2_distal">
    <visual>
      <origin rpy="0 3.14159265359 0" xyz="0 0 0" />
      <geometry>
        <mesh filename="package://hand/urdf/meshes/visual/distal.dae"/>
      </geometry>
      <material name="lightgray"/>
    </visual>
<!--    <collision>-->
<!--      <origin rpy="0 3.14159265359 0" xyz="0 0 0" />-->
<!--      <geometry>-->
<!--        <mesh filename="package://hand/urdf/meshes/collision/distal.obj"/>-->
<!--      </geometry>-->
<!--    </collision>-->
    <collision name="tip">
      <origin rpy="-1.57079633 1.57079633 0" xyz="0.0 0.1043 0.0"/>
      <geometry>
        <sphere radius="0.019"/>
      </geometry>
    </collision>
    <collision name="body">
      <origin rpy="-1.57079633 1.57079633 0" xyz="0 0.06358 0.0"/>
      <geometry>
        <cylinder length="0.0815" radius="0.019"/>
      </geometry>
    </collision>
    <inertial>
      <mass value="0.11"/>
      <inertia ixx="0.01" ixy="0.00" ixz="0.00" iyy="0.01" iyz="0.0" izz="0.01"/>
      <!-- inertia is recomputed when loading asset  -->
    </inertial>
  </link>
  <link name="finger2_distal_tip">
<!--    <visual name="tip">-->
<!--      <origin xyz="0 0 0"/>-->
<!--      <geometry>-->
<!--        <sphere radius="0.019"/>-->
<!--      </geometry>-->
<!--    </visual>-->
<!--    <visual name="body">-->
<!--      <origin xyz="0 0 -0.03075"/>-->
<!--      <geometry>-->
<!--        <cylinder length="0.0615" radius="0.019"/>-->
<!--      </geometry>-->
<!--    </visual>-->
<!--    <collision name="tip">-->
<!--      <origin xyz="0 0 0"/>-->
<!--      <geometry>-->
<!--        <sphere radius="0.019"/>-->
<!--      </geometry>-->
<!--    </collision>-->
<!--    <collision name="body">-->
<!--      <origin xyz="0 0 -0.03075"/>-->
<!--      <geometry>-->
<!--        <cylinder length="0.0615" radius="0.019"/>-->
<!--      </geometry>-->
<!--    </collision>-->
<!--    <inertial>-->
<!--      <mass value="0.05"/>-->
<!--      <inertia ixx="0.01" ixy="0.00" ixz="0.00" iyy="0.01" iyz="0.0" izz="0.01"/>-->
<!--      &lt;!&ndash; inertia is recomputed when loading asset  &ndash;&gt;-->
<!--    </inertial>-->
  </link>
  <joint name="finger2_proximal_joint" type="revolute">
    <parent link="palm_link"/>
    <child link="finger2_proximal"/>
    <origin rpy="1.57079633 0 2.82743338823" xyz="0.043701602 0.134499702 0.041"/>
    <axis xyz="0 1 0"/>
    <limit effort="4" velocity="1.0" lower="-1.0" upper="1.0"/>
  </joint>
  <joint name="finger2_middle_joint" type="revolute">
    <parent link="finger2_proximal"/>
    <child link="finger2_middle"/>
    <origin rpy="0 0 0" xyz="0.0 0.0655 0.0"/>
    <axis xyz="-1 0 0"/>
    <limit effort="4" velocity="1.0" lower="0.0" upper="1.0"/>
  </joint>
  <joint name="finger2_distal_joint" type="revolute">
    <parent link="finger2_middle"/>
    <child link="finger2_distal"/>
    <origin rpy="0 0 0" xyz="0.0 0.069 0.0"/>
    <axis xyz="-1 0 0"/>
    <limit effort="4" velocity="1.0" lower="0.0" upper="1.0"/>
  </joint>
  <joint name="finger2_distal_tip_joint" type="fixed">
    <parent link="finger2_distal"/>
    <child link="finger2_distal_tip"/>
    <origin rpy="-1.57079633 1.57079633 0" xyz="0.0 0.1035 0.0"/>
  </joint>


  <!-- Finger 3 -->
  <link name="finger3_proximal">
     <visual>
      <origin rpy="0 0 0" xyz="0 0 0" />
      <geometry>
        <mesh filename="package://hand/urdf/meshes/visual/proximal.dae"/>
      </geometry>
      <material name="gray"/>
    </visual>
    <collision>
      <origin rpy="0 0 0" xyz="0 0 0" />
      <geometry>
        <mesh filename="package://hand/urdf/meshes/collision/proximal.obj"/>
      </geometry>
    </collision>
     <inertial>
      <mass value="0.100"/>
    </inertial>
  </link>
  <link name="finger3_middle">
    <visual>
      <origin rpy="0 0 0" xyz="0 0 0" />
      <geometry>
        <mesh filename="package://hand/urdf/meshes/visual/middle.dae"/>
      </geometry>
      <material name="gray"/>
    </visual>
    <collision>
      <origin rpy="0 0 0" xyz="0 0 0" />
      <geometry>
        <mesh filename="package://hand/urdf/meshes/collision/middle.obj"/>
      </geometry>
    </collision>
    <inertial>
      <mass value="0.100"/>
    </inertial>
  </link>
  <link name="finger3_distal">
    <visual>
      <origin rpy="0 3.14159265359 0" xyz="0 0 0" />
      <geometry>
        <mesh filename="package://hand/urdf/meshes/visual/distal.dae"/>
      </geometry>
      <material name="lightgray"/>
    </visual>
<!--    <collision>-->
<!--      <origin rpy="0 3.14159265359 0" xyz="0 0 0" />-->
<!--      <geometry>-->
<!--        <mesh filename="package://hand/urdf/meshes/collision/distal.obj"/>-->
<!--      </geometry>-->
<!--    </collision>-->
    <collision name="tip">
      <origin rpy="-1.57079633 1.57079633 0" xyz="0.0 0.1043 0.0"/>
      <geometry>
        <sphere radius="0.019"/>
      </geometry>
    </collision>
    <collision name="body">
      <origin rpy="-1.57079633 1.57079633 0" xyz="0 0.06358 0.0"/>
      <geometry>
        <cylinder length="0.0815" radius="0.019"/>
      </geometry>
    </collision>
    <inertial>
      <mass value="0.11"/>
      <inertia ixx="0.01" ixy="0.00" ixz="0.00" iyy="0.01" iyz="0.0" izz="0.01"/>
      <!-- inertia is recomputed when loading asset  -->
    </inertial>
  </link>
  <link name="finger3_distal_tip">
<!--       <visual name="tip">-->
<!--      <origin xyz="0 0 0"/>-->
<!--      <geometry>-->
<!--        <sphere radius="0.019"/>-->
<!--      </geometry>-->
<!--    </visual>-->
<!--    <visual name="body">-->
<!--      <origin xyz="0 0 -0.03075"/>-->
<!--      <geometry>-->
<!--        <cylinder length="0.0615" radius="0.019"/>-->
<!--      </geometry>-->
<!--    </visual>-->
<!--    <collision name="tip">-->
<!--      <origin xyz="0 0 0"/>-->
<!--      <geometry>-->
<!--        <sphere radius="0.019"/>-->
<!--      </geometry>-->
<!--    </collision>-->
<!--    <collision name="body">-->
<!--      <origin xyz="0 0 -0.03075"/>-->
<!--      <geometry>-->
<!--        <cylinder length="0.0615" radius="0.019"/>-->
<!--      </geometry>-->
<!--    </collision>-->
<!--    <inertial>-->
<!--      <mass value="0.11"/>-->
<!--      <inertia ixx="0.01" ixy="0.00" ixz="0.00" iyy="0.01" iyz="0.0" izz="0.01"/>-->
<!--      &lt;!&ndash; inertia is recomputed when loading asset  &ndash;&gt;-->
<!--    </inertial>-->
  </link>
  <joint name="finger3_proximal_joint" type="revolute">
    <parent link="palm_link"/>
    <child link="finger3_proximal"/>
    <origin rpy="1.57079633 0 -2.19911485751" xyz="-0.114412281  0.083125388  0.041"/>
    <axis xyz="0 1 0"/>
    <limit effort="4" velocity="1.0" lower="-1.0" upper="1.0"/>
  </joint>
  <joint name="finger3_middle_joint" type="revolute">
    <parent link="finger3_proximal"/>
    <child link="finger3_middle"/>
    <origin rpy="0 0 0" xyz="0.0 0.0655 0.0"/>
    <axis xyz="-1 0 0"/>
    <limit effort="4" velocity="1.0" lower="0.0" upper="1.0"/>
  </joint>
  <joint name="finger3_distal_joint" type="revolute">
    <parent link="finger3_middle"/>
    <child link="finger3_distal"/>
    <origin rpy="0 0 0" xyz="0.0 0.069 0.0"/>
    <axis xyz="-1 0 0"/>
    <limit effort="4" velocity="1.0" lower="0.0" upper="1.0"/>
  </joint>
  <joint name="finger3_distal_tip_joint" type="fixed">
    <parent link="finger3_distal"/>
    <child link="finger3_distal_tip"/>
    <origin rpy="-1.57079633 1.57079633 0" xyz="0.0 0.1035 0.0"/>
  </joint>

  <!-- Finger 4 -->
  <link name="finger4_proximal">
     <visual>
      <origin rpy="0 0 0" xyz="0 0 0" />
      <geometry>
        <mesh filename="package://hand/urdf/meshes/visual/proximal.dae"/>
      </geometry>
      <material name="gray"/>
    </visual>
    <collision>
      <origin rpy="0 0 0" xyz="0 0 0" />
      <geometry>
        <mesh filename="package://hand/urdf/meshes/collision/proximal.obj"/>
      </geometry>
    </collision>
    <inertial>
      <mass value="0.100"/>
    </inertial>
  </link>
  <link name="finger4_middle">
   <visual>
      <origin rpy="0 0 0" xyz="0 0 0" />
      <geometry>
        <mesh filename="package://hand/urdf/meshes/visual/middle.dae"/>
      </geometry>
      <material name="gray"/>
    </visual>
    <collision>
      <origin rpy="0 0 0" xyz="0 0 0" />
      <geometry>
        <mesh filename="package://hand/urdf/meshes/collision/middle.obj"/>
      </geometry>
    </collision>
    <inertial>
      <mass value="0.100"/>
    </inertial>
  </link>
  <link name="finger4_distal">
    <visual>
      <origin rpy="0 3.14159265359 0" xyz="0 0 0" />
      <geometry>
        <mesh filename="package://hand/urdf/meshes/visual/distal.dae"/>
      </geometry>
      <material name="lightgray"/>
    </visual>
<!--    <collision>-->
<!--      <origin rpy="0 3.14159265359 0" xyz="0 0 0" />-->
<!--      <geometry>-->
<!--        <mesh filename="package://hand/urdf/meshes/collision/distal.obj"/>-->
<!--      </geometry>-->
<!--    </collision>-->
    <collision name="tip">
      <origin rpy="-1.57079633 1.57079633 0" xyz="0.0 0.1043 0.0"/>
      <geometry>
        <sphere radius="0.019"/>
      </geometry>
    </collision>
    <collision name="body">
      <origin rpy="-1.57079633 1.57079633 0" xyz="0 0.06358 0.0"/>
      <geometry>
        <cylinder length="0.0815" radius="0.019"/>
      </geometry>
    </collision>
    <inertial>
      <mass value="0.11"/>
      <inertia ixx="0.01" ixy="0.00" ixz="0.00" iyy="0.01" iyz="0.0" izz="0.01"/>
      <!-- inertia is recomputed when loading asset  -->
    </inertial>
  </link>
  <link name="finger4_distal_tip">
<!--       <visual name="tip">-->
<!--      <origin xyz="0 0 0"/>-->
<!--      <geometry>-->
<!--        <sphere radius="0.019"/>-->
<!--      </geometry>-->
<!--    </visual>-->
<!--    <visual name="body">-->
<!--      <origin xyz="0 0 -0.03075"/>-->
<!--      <geometry>-->
<!--        <cylinder length="0.0615" radius="0.019"/>-->
<!--      </geometry>-->
<!--    </visual>-->
<!--    <collision name="tip">-->
<!--      <origin xyz="0 0 0"/>-->
<!--      <geometry>-->
<!--        <sphere radius="0.019"/>-->
<!--      </geometry>-->
<!--    </collision>-->
<!--    <collision name="body">-->
<!--      <origin xyz="0 0 -0.03075"/>-->
<!--      <geometry>-->
<!--        <cylinder length="0.0615" radius="0.019"/>-->
<!--      </geometry>-->
<!--    </collision>-->
<!--    <inertial>-->
<!--      <mass value="0.05"/>-->
<!--      <inertia ixx="0.01" ixy="0.00" ixz="0.00" iyy="0.01" iyz="0.0" izz="0.01"/>-->
<!--      &lt;!&ndash; inertia is recomputed when loading asset  &ndash;&gt;-->
<!--    </inertial>-->
  </link>
  <joint name="finger4_proximal_joint" type="revolute">
    <parent link="palm_link"/>
    <child link="finger4_proximal"/>
    <origin rpy="1.57079633 0 -0.94247779607" xyz="-0.114412281 -0.083125388  0.041"/>
    <axis xyz="0 1 0"/>
    <limit effort="4" velocity="1.0" lower="-1.0" upper="1.0"/>
  </joint>
  <joint name="finger4_middle_joint" type="revolute">
    <parent link="finger4_proximal"/>
    <child link="finger4_middle"/>
    <origin rpy="0 0 0" xyz="0.0 0.0655 0.0"/>
    <axis xyz="-1 0 0"/>
    <limit effort="4" velocity="1.0" lower="0.0" upper="1.0"/>
  </joint>
  <joint name="finger4_distal_joint" type="revolute">
    <parent link="finger4_middle"/>
    <child link="finger4_distal"/>
    <origin rpy="0 0 0" xyz="0.0 0.069 0.0"/>
    <axis xyz="-1 0 0"/>
    <limit effort="4" velocity="1.0" lower="0.0" upper="1.0"/>
  </joint>
  <joint name="finger4_distal_tip_joint" type="fixed">
    <parent link="finger4_distal"/>
    <child link="finger4_distal_tip"/>
    <origin rpy="-1.57079633 1.57079633 0" xyz="0.0 0.1035 0.0"/>
  </joint>


  <!-- Finger 5 -->
  <link name="finger5_proximal">
     <visual>
      <origin rpy="0 0 0" xyz="0 0 0" />
      <geometry>
        <mesh filename="package://hand/urdf/meshes/visual/proximal.dae"/>
      </geometry>
      <material name="gray"/>
    </visual>
    <collision>
      <origin rpy="0 0 0" xyz="0 0 0" />
      <geometry>
        <mesh filename="package://hand/urdf/meshes/collision/proximal.obj"/>
      </geometry>
    </collision>
    <inertial>
      <mass value="0.100"/>
    </inertial>
  </link>
  <link name="finger5_middle">
    <visual>
      <origin rpy="0 0 0" xyz="0 0 0" />
      <geometry>
        <mesh filename="package://hand/urdf/meshes/visual/middle.dae"/>
      </geometry>
      <material name="gray"/>
    </visual>
    <collision>
      <origin rpy="0 0 0" xyz="0 0 0" />
      <geometry>
        <mesh filename="package://hand/urdf/meshes/collision/middle.obj"/>
      </geometry>
    </collision>
    <inertial>
      <mass value="0.100"/>
    </inertial>
  </link>
  <link name="finger5_distal">
    <visual>
      <origin rpy="0 3.14159265359 0" xyz="0 0 0"/>
      <geometry>
        <mesh filename="package://hand/urdf/meshes/visual/distal.dae"/>
      </geometry>
      <material name="lightgray"/>
    </visual>
<!--    <collision>-->
<!--      <origin rpy="0 3.14159265359 0" xyz="0 0 0" />-->
<!--      <geometry>-->
<!--        <mesh filename="package://hand/urdf/meshes/collision/distal.obj"/>-->
<!--      </geometry>-->
<!--    </collision>-->
    <collision name="tip">
      <origin rpy="-1.57079633 1.57079633 0" xyz="0.0 0.1043 0.0"/>
      <geometry>
        <sphere radius="0.019"/>
      </geometry>
    </collision>
    <collision name="body">
      <origin rpy="-1.57079633 1.57079633 0" xyz="0 0.06358 0.0"/>
      <geometry>
        <cylinder length="0.0815" radius="0.019"/>
      </geometry>
    </collision>
    <inertial>
      <mass value="0.11"/>
      <inertia ixx="0.01" ixy="0.00" ixz="0.00" iyy="0.01" iyz="0.0" izz="0.01"/>
      <!-- inertia is recomputed when loading asset  -->
    </inertial>
  </link>
  <link name="finger5_distal_tip">
<!--       <visual name="tip">-->
<!--      <origin xyz="0 0 0"/>-->
<!--      <geometry>-->
<!--        <sphere radius="0.019"/>-->
<!--      </geometry>-->
<!--    </visual>-->
<!--    <visual name="body">-->
<!--      <origin xyz="0 0 -0.03075"/>-->
<!--      <geometry>-->
<!--        <cylinder length="0.0615" radius="0.019"/>-->
<!--      </geometry>-->
<!--    </visual>-->
<!--    <collision name="tip">-->
<!--      <origin xyz="0 0 0"/>-->
<!--      <geometry>-->
<!--        <sphere radius="0.019"/>-->
<!--      </geometry>-->
<!--    </collision>-->
<!--    <collision name="body">-->
<!--      <origin xyz="0 0 -0.03075"/>-->
<!--      <geometry>-->
<!--        <cylinder length="0.0615" radius="0.019"/>-->
<!--      </geometry>-->
<!--    </collision>-->
<!--    <inertial>-->
<!--      <mass value="0.05"/>-->
<!--      <inertia ixx="0.01" ixy="0.00" ixz="0.00" iyy="0.01" iyz="0.0" izz="0.01"/>-->
<!--      &lt;!&ndash; inertia is recomputed when loading asset  &ndash;&gt;-->
<!--    </inertial>-->
  </link>
  <joint name="finger5_proximal_joint" type="revolute">
    <parent link="palm_link"/>
    <child link="finger5_proximal"/>
    <origin rpy="1.57079633 0 0.31415926535" xyz="0.043701602 -0.134499702  0.041"/>
    <axis xyz="0 1 0"/>
    <limit effort="4" velocity="1.0" lower="-1.0" upper="1.0"/>
  </joint>
  <joint name="finger5_middle_joint" type="revolute">
    <parent link="finger5_proximal"/>
    <child link="finger5_middle"/>
    <origin rpy="0 0 0" xyz="0.0 0.0655 0.0"/>
    <axis xyz="-1 0 0"/>
    <limit effort="4" velocity="1.0" lower="0.0" upper="1.0"/>
  </joint>
  <joint name="finger5_distal_joint" type="revolute">
    <parent link="finger5_middle"/>
    <child link="finger5_distal"/>
    <origin rpy="0 0 0" xyz="0.0 0.069 0.0"/>
    <axis xyz="-1 0 0"/>
    <limit effort="4" velocity="1.0" lower="0.0" upper="1.0"/>
  </joint>
  <joint name="finger5_distal_tip_joint" type="fixed">
    <parent link="finger5_distal"/>
    <child link="finger5_distal_tip"/>
    <origin rpy="-1.57079633 1.57079633 0" xyz="0.0 0.1035 0.0"/>
  </joint>
</robot>
